{"url":"https://api.github.com/repos/ludwig-ai/ludwig/issues/100","repository_url":"https://api.github.com/repos/ludwig-ai/ludwig","labels_url":"https://api.github.com/repos/ludwig-ai/ludwig/issues/100/labels{/name}","comments_url":"https://api.github.com/repos/ludwig-ai/ludwig/issues/100/comments","events_url":"https://api.github.com/repos/ludwig-ai/ludwig/issues/100/events","html_url":"https://github.com/ludwig-ai/ludwig/issues/100","id":410951877,"node_id":"MDU6SXNzdWU0MTA5NTE4Nzc=","number":100,"title":"Cannot feed value of shape for Tensor when predicting model with image","user":{"login":"abogoyavlensky","id":1375411,"node_id":"MDQ6VXNlcjEzNzU0MTE=","avatar_url":"https://avatars.githubusercontent.com/u/1375411?v=4","gravatar_id":"","url":"https://api.github.com/users/abogoyavlensky","html_url":"https://github.com/abogoyavlensky","followers_url":"https://api.github.com/users/abogoyavlensky/followers","following_url":"https://api.github.com/users/abogoyavlensky/following{/other_user}","gists_url":"https://api.github.com/users/abogoyavlensky/gists{/gist_id}","starred_url":"https://api.github.com/users/abogoyavlensky/starred{/owner}{/repo}","subscriptions_url":"https://api.github.com/users/abogoyavlensky/subscriptions","organizations_url":"https://api.github.com/users/abogoyavlensky/orgs","repos_url":"https://api.github.com/users/abogoyavlensky/repos","events_url":"https://api.github.com/users/abogoyavlensky/events{/privacy}","received_events_url":"https://api.github.com/users/abogoyavlensky/received_events","type":"User","site_admin":false},"labels":[{"id":1174068769,"node_id":"MDU6TGFiZWwxMTc0MDY4NzY5","url":"https://api.github.com/repos/ludwig-ai/ludwig/labels/bug","name":"bug","color":"d73a4a","default":true,"description":"Something isn't working"},{"id":1174068775,"node_id":"MDU6TGFiZWwxMTc0MDY4Nzc1","url":"https://api.github.com/repos/ludwig-ai/ludwig/labels/waiting%20for%20answer","name":"waiting for answer","color":"fff36b","default":false,"description":"Further information is requested"}],"state":"closed","locked":false,"assignee":null,"assignees":[],"milestone":null,"comments":18,"created_at":"2019-02-15T21:29:11Z","updated_at":"2019-03-27T06:47:39Z","closed_at":"2019-03-27T06:47:39Z","author_association":"NONE","active_lock_reason":null,"body":"I get this error when trying to perform prediction with a new image on trained model:\r\n```\r\nTraceback (most recent call last):\r\n  File \"/home/andrey/.venvs/ludwig-learn/bin/ludwig\", line 11, in <module>\r\n    sys.exit(main())\r\n  File \"/home/andrey/.venvs/ludwig-learn/lib/python3.6/site-packages/ludwig/cli.py\", line 86, in main\r\n    CLI()\r\n  File \"/home/andrey/.venvs/ludwig-learn/lib/python3.6/site-packages/ludwig/cli.py\", line 64, in __init__\r\n    getattr(self, args.command)()\r\n  File \"/home/andrey/.venvs/ludwig-learn/lib/python3.6/site-packages/ludwig/cli.py\", line 73, in predict\r\n    predict.cli(sys.argv[2:])\r\n  File \"/home/andrey/.venvs/ludwig-learn/lib/python3.6/site-packages/ludwig/predict.py\", line 379, in cli\r\n    full_predict(**vars(args))\r\n  File \"/home/andrey/.venvs/ludwig-learn/lib/python3.6/site-packages/ludwig/predict.py\", line 104, in full_predict\r\n    debug\r\n  File \"/home/andrey/.venvs/ludwig-learn/lib/python3.6/site-packages/ludwig/predict.py\", line 173, in predict\r\n    gpu_fraction=gpu_fraction\r\n  File \"/home/andrey/.venvs/ludwig-learn/lib/python3.6/site-packages/ludwig/models/model.py\", line 1182, in predict\r\n    only_predictions=only_predictions\r\n  File \"/home/andrey/.venvs/ludwig-learn/lib/python3.6/site-packages/ludwig/models/model.py\", line 756, in batch_evaluation\r\n    is_training=is_training\r\n  File \"/home/andrey/.venvs/ludwig-learn/lib/python3.6/site-packages/tensorflow/python/client/session.py\", line 929, in run\r\n    run_metadata_ptr)\r\n  File \"/home/andrey/.venvs/ludwig-learn/lib/python3.6/site-packages/tensorflow/python/client/session.py\", line 1128, in _run\r\n    str(subfeed_t.get_shape())))\r\nValueError: Cannot feed value of shape (1,) for Tensor 'image_path/image_path:0', which has shape '(?, 100, 100, 3)'\r\n```\r\n\r\nThe model definition I use:\r\n```\r\ninput_features:\r\n    -\r\n        name: image_path\r\n        type: image\r\n        encoder: stacked_cnn\r\n        in_memory: false\r\n        height: 100\r\n        width: 100\r\n\r\noutput_features:\r\n    -\r\n        name: tags\r\n        type: set`\r\n```\r\n\r\nExample of testing csv-file:\r\n```\r\nimage_path,tags\r\ntestdata/cat.101.jpg\r\n```\r\n\r\nI've tried output features with category and set types but eventually get that error.","closed_by":{"login":"w4nderlust","id":349256,"node_id":"MDQ6VXNlcjM0OTI1Ng==","avatar_url":"https://avatars.githubusercontent.com/u/349256?v=4","gravatar_id":"","url":"https://api.github.com/users/w4nderlust","html_url":"https://github.com/w4nderlust","followers_url":"https://api.github.com/users/w4nderlust/followers","following_url":"https://api.github.com/users/w4nderlust/following{/other_user}","gists_url":"https://api.github.com/users/w4nderlust/gists{/gist_id}","starred_url":"https://api.github.com/users/w4nderlust/starred{/owner}{/repo}","subscriptions_url":"https://api.github.com/users/w4nderlust/subscriptions","organizations_url":"https://api.github.com/users/w4nderlust/orgs","repos_url":"https://api.github.com/users/w4nderlust/repos","events_url":"https://api.github.com/users/w4nderlust/events{/privacy}","received_events_url":"https://api.github.com/users/w4nderlust/received_events","type":"User","site_admin":false},"reactions":{"url":"https://api.github.com/repos/ludwig-ai/ludwig/issues/100/reactions","total_count":0,"+1":0,"-1":0,"laugh":0,"hooray":0,"confused":0,"heart":0,"rocket":0,"eyes":0},"timeline_url":"https://api.github.com/repos/ludwig-ai/ludwig/issues/100/timeline","performed_via_github_app":null,"state_reason":"completed"}