{"url":"https://api.github.com/repos/mnicnc404/CartoonGan-tensorflow/issues/48","repository_url":"https://api.github.com/repos/mnicnc404/CartoonGan-tensorflow","labels_url":"https://api.github.com/repos/mnicnc404/CartoonGan-tensorflow/issues/48/labels{/name}","comments_url":"https://api.github.com/repos/mnicnc404/CartoonGan-tensorflow/issues/48/comments","events_url":"https://api.github.com/repos/mnicnc404/CartoonGan-tensorflow/issues/48/events","html_url":"https://github.com/mnicnc404/CartoonGan-tensorflow/issues/48","id":825172465,"node_id":"MDU6SXNzdWU4MjUxNzI0NjU=","number":48,"title":"Images are not processing and saving into output_images directory","user":{"login":"akay4ty7","id":55038456,"node_id":"MDQ6VXNlcjU1MDM4NDU2","avatar_url":"https://avatars.githubusercontent.com/u/55038456?v=4","gravatar_id":"","url":"https://api.github.com/users/akay4ty7","html_url":"https://github.com/akay4ty7","followers_url":"https://api.github.com/users/akay4ty7/followers","following_url":"https://api.github.com/users/akay4ty7/following{/other_user}","gists_url":"https://api.github.com/users/akay4ty7/gists{/gist_id}","starred_url":"https://api.github.com/users/akay4ty7/starred{/owner}{/repo}","subscriptions_url":"https://api.github.com/users/akay4ty7/subscriptions","organizations_url":"https://api.github.com/users/akay4ty7/orgs","repos_url":"https://api.github.com/users/akay4ty7/repos","events_url":"https://api.github.com/users/akay4ty7/events{/privacy}","received_events_url":"https://api.github.com/users/akay4ty7/received_events","type":"User","site_admin":false},"labels":[],"state":"open","locked":true,"assignee":null,"assignees":[],"milestone":null,"comments":0,"created_at":"2021-03-09T02:02:57Z","updated_at":"2021-03-09T02:16:08Z","closed_at":null,"author_association":"NONE","active_lock_reason":null,"body":"![image](https://user-images.githubusercontent.com/55038456/110408406-5adbf800-80ea-11eb-9a18-625ad18480c4.png)\r\n\r\n\r\nHello,\r\n\r\nI'm currently having some issues when testing cartoonize.py. It seems as though the transforming of the image is not happening as shown above, the loading bar remains at 0%. I also have run into the following issues:\r\n\r\n```\r\nTraceback (most recent call last):\r\n  File \"cartoonize.py\", line 371, in <module>\r\n    main()\r\n  File \"cartoonize.py\", line 356, in main\r\n    transformed_image_path = save_transformed_image(output_image, image_filename, save_dir)\r\n  File \"cartoonize.py\", line 126, in save_transformed_image\r\n    image.save(transformed_image_path)\r\n  File \"D:\\Python 3.6\\lib\\site-packages\\PIL\\Image.py\", line 2161, in save\r\n    fp = builtins.open(filename, \"w+b\")\r\nFileNotFoundError: [Errno 2] No such file or directory: 'output_images\\\\shinkai\\\\input_images\\\\origami.jpg'\r\n```\r\n\r\nI would greatly appreciate some solutions.","closed_by":null,"reactions":{"url":"https://api.github.com/repos/mnicnc404/CartoonGan-tensorflow/issues/48/reactions","total_count":0,"+1":0,"-1":0,"laugh":0,"hooray":0,"confused":0,"heart":0,"rocket":0,"eyes":0},"timeline_url":"https://api.github.com/repos/mnicnc404/CartoonGan-tensorflow/issues/48/timeline","performed_via_github_app":null,"state_reason":null}