{"url":"https://api.github.com/repos/jgraving/DeepPoseKit/issues/72","repository_url":"https://api.github.com/repos/jgraving/DeepPoseKit","labels_url":"https://api.github.com/repos/jgraving/DeepPoseKit/issues/72/labels{/name}","comments_url":"https://api.github.com/repos/jgraving/DeepPoseKit/issues/72/comments","events_url":"https://api.github.com/repos/jgraving/DeepPoseKit/issues/72/events","html_url":"https://github.com/jgraving/DeepPoseKit/issues/72","id":758914901,"node_id":"MDU6SXNzdWU3NTg5MTQ5MDE=","number":72,"title":"Unable to open object (object 'logs' doesn't exist)","user":{"login":"albertoursino","id":56396708,"node_id":"MDQ6VXNlcjU2Mzk2NzA4","avatar_url":"https://avatars.githubusercontent.com/u/56396708?v=4","gravatar_id":"","url":"https://api.github.com/users/albertoursino","html_url":"https://github.com/albertoursino","followers_url":"https://api.github.com/users/albertoursino/followers","following_url":"https://api.github.com/users/albertoursino/following{/other_user}","gists_url":"https://api.github.com/users/albertoursino/gists{/gist_id}","starred_url":"https://api.github.com/users/albertoursino/starred{/owner}{/repo}","subscriptions_url":"https://api.github.com/users/albertoursino/subscriptions","organizations_url":"https://api.github.com/users/albertoursino/orgs","repos_url":"https://api.github.com/users/albertoursino/repos","events_url":"https://api.github.com/users/albertoursino/events{/privacy}","received_events_url":"https://api.github.com/users/albertoursino/received_events","type":"User","site_admin":false},"labels":[],"state":"closed","locked":false,"assignee":null,"assignees":[],"milestone":null,"comments":1,"created_at":"2020-12-07T22:59:05Z","updated_at":"2020-12-08T15:35:14Z","closed_at":"2020-12-08T01:37:21Z","author_association":"NONE","active_lock_reason":null,"body":"Can someone help me with this error?\r\n\r\n```python\r\nEpoch 00001: loss improved from inf to 31.71337, saving model to C:/Users/Alberto Ursino/Desktop/IntellIj Local Files/DeepPoseKit/alberto/deepposekit-data/datasets/dog/log_densenet.h5\r\nC:\\Users\\Alberto Ursino\\Desktop\\IntellIj Local Files\\DeepPoseKit\\deepposekit\\models\\engine.py:196: UserWarning: `n_validation` is 0, so the training set will be used for model evaluation\r\n  \"`n_validation` is 0, so the training set will be used for model evaluation\"\r\nTraceback (most recent call last):\r\n  File \"C:/Users/Alberto Ursino/Desktop/IntellIj Local Files/DeepPoseKit/alberto/annotation/train.py\", line 180, in <module>\r\n    steps_per_epoch=1,\r\n  File \"C:\\Users\\Alberto Ursino\\Desktop\\IntellIj Local Files\\DeepPoseKit\\deepposekit\\models\\engine.py\", line 174, in fit\r\n    **kwargs\r\n  File \"C:\\Users\\Alberto Ursino\\anaconda3\\envs\\TensorFlow 1x\\lib\\site-packages\\tensorflow\\python\\keras\\engine\\training.py\", line 1433, in fit_generator\r\n    steps_name='steps_per_epoch')\r\n  File \"C:\\Users\\Alberto Ursino\\anaconda3\\envs\\TensorFlow 1x\\lib\\site-packages\\tensorflow\\python\\keras\\engine\\training_generator.py\", line 331, in model_iteration\r\n    callbacks.on_epoch_end(epoch, epoch_logs)\r\n  File \"C:\\Users\\Alberto Ursino\\anaconda3\\envs\\TensorFlow 1x\\lib\\site-packages\\tensorflow\\python\\keras\\callbacks.py\", line 311, in on_epoch_end\r\n    callback.on_epoch_end(epoch, logs)\r\n  File \"C:\\Users\\Alberto Ursino\\Desktop\\IntellIj Local Files\\DeepPoseKit\\deepposekit\\callbacks.py\", line 126, in on_epoch_end\r\n    data = h5file[\"logs\"][key]\r\n  File \"h5py\\_objects.pyx\", line 54, in h5py._objects.with_phil.wrapper\r\n  File \"h5py\\_objects.pyx\", line 55, in h5py._objects.with_phil.wrapper\r\n  File \"C:\\Users\\Alberto Ursino\\anaconda3\\envs\\TensorFlow 1x\\lib\\site-packages\\h5py\\_hl\\group.py\", line 264, in __getitem__\r\n    oid = h5o.open(self.id, self._e(name), lapl=self._lapl)\r\n  File \"h5py\\_objects.pyx\", line 54, in h5py._objects.with_phil.wrapper\r\n  File \"h5py\\_objects.pyx\", line 55, in h5py._objects.with_phil.wrapper\r\n  File \"h5py\\h5o.pyx\", line 190, in h5py.h5o.open\r\nKeyError: \"Unable to open object (object 'logs' doesn't exist)\"\r\n```\r\n\r\nThese are the parameters I have set:\r\n```python\r\nmodel.fit(\r\n    batch_size=16,\r\n    validation_batch_size=10,\r\n    callbacks=callbacks,\r\n    #epochs=1000, # Increase the number of epochs to train the model longer\r\n    epochs=200,\r\n    n_workers=8,\r\n    steps_per_epoch=1,\r\n)\r\n```","closed_by":{"login":"albertoursino","id":56396708,"node_id":"MDQ6VXNlcjU2Mzk2NzA4","avatar_url":"https://avatars.githubusercontent.com/u/56396708?v=4","gravatar_id":"","url":"https://api.github.com/users/albertoursino","html_url":"https://github.com/albertoursino","followers_url":"https://api.github.com/users/albertoursino/followers","following_url":"https://api.github.com/users/albertoursino/following{/other_user}","gists_url":"https://api.github.com/users/albertoursino/gists{/gist_id}","starred_url":"https://api.github.com/users/albertoursino/starred{/owner}{/repo}","subscriptions_url":"https://api.github.com/users/albertoursino/subscriptions","organizations_url":"https://api.github.com/users/albertoursino/orgs","repos_url":"https://api.github.com/users/albertoursino/repos","events_url":"https://api.github.com/users/albertoursino/events{/privacy}","received_events_url":"https://api.github.com/users/albertoursino/received_events","type":"User","site_admin":false},"reactions":{"url":"https://api.github.com/repos/jgraving/DeepPoseKit/issues/72/reactions","total_count":0,"+1":0,"-1":0,"laugh":0,"hooray":0,"confused":0,"heart":0,"rocket":0,"eyes":0},"timeline_url":"https://api.github.com/repos/jgraving/DeepPoseKit/issues/72/timeline","performed_via_github_app":null,"state_reason":"completed"}