{"url":"https://api.github.com/repos/ultralytics/yolov3/issues/609","repository_url":"https://api.github.com/repos/ultralytics/yolov3","labels_url":"https://api.github.com/repos/ultralytics/yolov3/issues/609/labels{/name}","comments_url":"https://api.github.com/repos/ultralytics/yolov3/issues/609/comments","events_url":"https://api.github.com/repos/ultralytics/yolov3/issues/609/events","html_url":"https://github.com/ultralytics/yolov3/issues/609","id":521912698,"node_id":"MDU6SXNzdWU1MjE5MTI2OTg=","number":609,"title":"Training error for custom data using transfer learning","user":{"login":"Pari-singh","id":24270022,"node_id":"MDQ6VXNlcjI0MjcwMDIy","avatar_url":"https://avatars.githubusercontent.com/u/24270022?v=4","gravatar_id":"","url":"https://api.github.com/users/Pari-singh","html_url":"https://github.com/Pari-singh","followers_url":"https://api.github.com/users/Pari-singh/followers","following_url":"https://api.github.com/users/Pari-singh/following{/other_user}","gists_url":"https://api.github.com/users/Pari-singh/gists{/gist_id}","starred_url":"https://api.github.com/users/Pari-singh/starred{/owner}{/repo}","subscriptions_url":"https://api.github.com/users/Pari-singh/subscriptions","organizations_url":"https://api.github.com/users/Pari-singh/orgs","repos_url":"https://api.github.com/users/Pari-singh/repos","events_url":"https://api.github.com/users/Pari-singh/events{/privacy}","received_events_url":"https://api.github.com/users/Pari-singh/received_events","type":"User","site_admin":false},"labels":[{"id":1035696370,"node_id":"MDU6TGFiZWwxMDM1Njk2Mzcw","url":"https://api.github.com/repos/ultralytics/yolov3/labels/bug","name":"bug","color":"d73a4a","default":true,"description":"Something isn't working"}],"state":"closed","locked":false,"assignee":null,"assignees":[],"milestone":null,"comments":4,"created_at":"2019-11-13T02:10:11Z","updated_at":"2019-11-13T18:21:24Z","closed_at":"2019-11-13T02:56:36Z","author_association":"NONE","active_lock_reason":null,"body":"Hi, I created the dataset as mentioned in the custom data training and everything seems good. But when I run the training command, I get this error: \r\n\r\n  0%|          | 0/659 [00:00<?, ?it/s]Traceback (most recent call last):\r\n  File \"train.py\", line 438, in <module>\r\n    train()  # train normally\r\n  File \"train.py\", line 237, in train\r\n    for i, (imgs, targets, paths, _) in pbar:  # batch -------------------------------------------------------------\r\n  File \"/my_project/lib/python3.5/site-packages/tqdm/std.py\", line 1091, in __iter__\r\n    for obj in iterable:\r\n  File \"/my_project/lib/python3.5/site-packages/torch/utils/data/dataloader.py\", line 819, in __next__\r\n    return self._process_data(data)\r\n  File \"i/my_project/lib/python3.5/site-packages/torch/utils/data/dataloader.py\", line 846, in _process_data\r\n    data.reraise()\r\n  File \"/my_project/lib/python3.5/site-packages/torch/_utils.py\", line 385, in reraise\r\n    raise self.exc_type(msg)\r\nValueError: Caught ValueError in DataLoader worker process 0.\r\nOriginal Traceback (most recent call last):\r\n  File \"my_project/lib/python3.5/site-packages/torch/utils/data/_utils/worker.py\", line 178, in _worker_loop\r\n    data = fetcher.fetch(index)\r\n  File \"my_project/lib/python3.5/site-packages/torch/utils/data/_utils/fetch.py\", line 44, in fetch\r\n    data = [self.dataset[idx] for idx in possibly_batched_index]\r\n  File \"/my_project/lib/python3.5/site-packages/torch/utils/data/_utils/fetch.py\", line 44, in <listcomp>\r\n    data = [self.dataset[idx] for idx in possibly_batched_index]\r\n  File \"yolov3/utils/datasets.py\", line 416, in __getitem__\r\n    img, labels = load_mosaic(self, index)\r\n  File \"yolov3/utils/datasets.py\", line 593, in load_mosaic\r\n    labels4 = np.concatenate(labels4, 0)\r\n  File \"<__array_function__ internals>\", line 6, in concatenate\r\nValueError: all the input arrays must have same number of dimensions, but the array at index 0 has 2 dimension(s) and the array at index 2 has 1 dimension(s)\r\n\r\n\r\n\r\nI am not sure why is this creating a trouble and how to fix this. I am following the steps mentioned and have done it previously successfully as well on different dataset. Any guidance will be appreciated.\r\nThanks ","closed_by":{"login":"glenn-jocher","id":26833433,"node_id":"MDQ6VXNlcjI2ODMzNDMz","avatar_url":"https://avatars.githubusercontent.com/u/26833433?v=4","gravatar_id":"","url":"https://api.github.com/users/glenn-jocher","html_url":"https://github.com/glenn-jocher","followers_url":"https://api.github.com/users/glenn-jocher/followers","following_url":"https://api.github.com/users/glenn-jocher/following{/other_user}","gists_url":"https://api.github.com/users/glenn-jocher/gists{/gist_id}","starred_url":"https://api.github.com/users/glenn-jocher/starred{/owner}{/repo}","subscriptions_url":"https://api.github.com/users/glenn-jocher/subscriptions","organizations_url":"https://api.github.com/users/glenn-jocher/orgs","repos_url":"https://api.github.com/users/glenn-jocher/repos","events_url":"https://api.github.com/users/glenn-jocher/events{/privacy}","received_events_url":"https://api.github.com/users/glenn-jocher/received_events","type":"User","site_admin":false},"reactions":{"url":"https://api.github.com/repos/ultralytics/yolov3/issues/609/reactions","total_count":0,"+1":0,"-1":0,"laugh":0,"hooray":0,"confused":0,"heart":0,"rocket":0,"eyes":0},"timeline_url":"https://api.github.com/repos/ultralytics/yolov3/issues/609/timeline","performed_via_github_app":null,"state_reason":"completed"}