{"url":"https://api.github.com/repos/mlflow/mlflow/issues/2113","repository_url":"https://api.github.com/repos/mlflow/mlflow","labels_url":"https://api.github.com/repos/mlflow/mlflow/issues/2113/labels{/name}","comments_url":"https://api.github.com/repos/mlflow/mlflow/issues/2113/comments","events_url":"https://api.github.com/repos/mlflow/mlflow/issues/2113/events","html_url":"https://github.com/mlflow/mlflow/issues/2113","id":524548098,"node_id":"MDU6SXNzdWU1MjQ1NDgwOTg=","number":2113,"title":"[SETUP-BUG] mlflow db upgrade fails on first deploy","user":{"login":"mbelang","id":5888932,"node_id":"MDQ6VXNlcjU4ODg5MzI=","avatar_url":"https://avatars.githubusercontent.com/u/5888932?v=4","gravatar_id":"","url":"https://api.github.com/users/mbelang","html_url":"https://github.com/mbelang","followers_url":"https://api.github.com/users/mbelang/followers","following_url":"https://api.github.com/users/mbelang/following{/other_user}","gists_url":"https://api.github.com/users/mbelang/gists{/gist_id}","starred_url":"https://api.github.com/users/mbelang/starred{/owner}{/repo}","subscriptions_url":"https://api.github.com/users/mbelang/subscriptions","organizations_url":"https://api.github.com/users/mbelang/orgs","repos_url":"https://api.github.com/users/mbelang/repos","events_url":"https://api.github.com/users/mbelang/events{/privacy}","received_events_url":"https://api.github.com/users/mbelang/received_events","type":"User","site_admin":false},"labels":[{"id":955449428,"node_id":"MDU6TGFiZWw5NTU0NDk0Mjg=","url":"https://api.github.com/repos/mlflow/mlflow/labels/bug","name":"bug","color":"d73a4a","default":true,"description":"Something isn't working"},{"id":1893072438,"node_id":"MDU6TGFiZWwxODkzMDcyNDM4","url":"https://api.github.com/repos/mlflow/mlflow/labels/help%20wanted","name":"help wanted","color":"c5def5","default":true,"description":"We would like help from the community to add this support"},{"id":2022849295,"node_id":"MDU6TGFiZWwyMDIyODQ5Mjk1","url":"https://api.github.com/repos/mlflow/mlflow/labels/area/tracking","name":"area/tracking","color":"48eabc","default":false,"description":"Tracking service, tracking client APIs, autologging"}],"state":"open","locked":false,"assignee":null,"assignees":[],"milestone":null,"comments":11,"created_at":"2019-11-18T18:44:22Z","updated_at":"2021-10-13T08:21:49Z","closed_at":null,"author_association":"NONE","active_lock_reason":null,"body":"- **OS Platform and Distribution (e.g., Linux Ubuntu 16.04)**: Debian Stretch\r\n- **MLflow installed from (source or binary)**: binary\r\n- **MLflow version (run ``mlflow --version``)**: 1.4.0\r\n- **Python version**: 3.6.8\r\n- **Exact command to reproduce**: `mlflow db upgrade` (ran before the server is actually started)\r\n\r\n### Describe the problem\r\nI'm deploying mlflow tracking server on Kubernetes and I run the `mlflow db upgrade` in an init container i.e before the server is actually started. That procedure worked fine if the server has started at least once before.\r\n\r\nSo when I deploy mlflow for the first time (empty db), the migration fails because I suspect that it is the tracking server that setup the db on first deployment. Am I right? \r\n\r\nIt would be nice if the DB would actually setup via the migration process or a separate command like `mlflow db init`. This command should be run multiple time without crashing. In other words it should be idempotent. As you can imagine the init-container will always be run before the server starts.\r\n\r\n### Other info / logs\r\nHere are the logs:\r\n\r\n```\r\n019/11/18 18:25:45 INFO mlflow.store.db.utils: Updating database tables at postgresql://dbadmin:wIZ4LFHfzxR96eOu04da@mlflow.c4ikfbyrjbf9.eu-central-1.rds.amazonaws.com:5432/mlflow in preparation for MLflow 1.0 schema migrations\r\nINFO  [alembic.runtime.migration] Context impl PostgresqlImpl.\r\nINFO  [alembic.runtime.migration] Will assume transactional DDL.\r\nINFO  [alembic.runtime.migration] Running upgrade  -> ff01da956556, ensure_unique_constraint_names\r\nTraceback (most recent call last):\r\n  File \"/usr/local/lib/python3.6/site-packages/sqlalchemy/engine/base.py\", line 1249, in _execute_context\r\n    cursor, statement, parameters, context\r\n  File \"/usr/local/lib/python3.6/site-packages/sqlalchemy/engine/default.py\", line 552, in do_execute\r\n    cursor.execute(statement, parameters)\r\npsycopg2.errors.UndefinedTable: relation \"experiments\" does not exist\r\n\r\n\r\nThe above exception was the direct cause of the following exception:\r\n\r\nTraceback (most recent call last):\r\n  File \"/usr/local/bin/mlflow\", line 8, in <module>\r\n    sys.exit(cli())\r\n  File \"/usr/local/lib/python3.6/site-packages/click/core.py\", line 764, in __call__\r\n    return self.main(*args, **kwargs)\r\n  File \"/usr/local/lib/python3.6/site-packages/click/core.py\", line 717, in main\r\n    rv = self.invoke(ctx)\r\n  File \"/usr/local/lib/python3.6/site-packages/click/core.py\", line 1137, in invoke\r\n    return _process_result(sub_ctx.command.invoke(sub_ctx))\r\n  File \"/usr/local/lib/python3.6/site-packages/click/core.py\", line 1137, in invoke\r\n    return _process_result(sub_ctx.command.invoke(sub_ctx))\r\n  File \"/usr/local/lib/python3.6/site-packages/click/core.py\", line 956, in invoke\r\n    return ctx.invoke(self.callback, **ctx.params)\r\n  File \"/usr/local/lib/python3.6/site-packages/click/core.py\", line 555, in invoke\r\n    return callback(*args, **kwargs)\r\n  File \"/usr/local/lib/python3.6/site-packages/mlflow/db.py\", line 28, in upgrade\r\n    mlflow.store.db.utils._upgrade_db_initialized_before_mlflow_1(url)\r\n  File \"/usr/local/lib/python3.6/site-packages/mlflow/store/db/utils.py\", line 155, in _upgrade_db_initialized_before_mlflow_1\r\n    command.upgrade(config, 'heads')\r\n  File \"/usr/local/lib/python3.6/site-packages/alembic/command.py\", line 279, in upgrade\r\n    script.run_env()\r\n  File \"/usr/local/lib/python3.6/site-packages/alembic/script/base.py\", line 475, in run_env\r\n    util.load_python_file(self.dir, \"env.py\")\r\n  File \"/usr/local/lib/python3.6/site-packages/alembic/util/pyfiles.py\", line 98, in load_python_file\r\n    module = load_module_py(module_id, path)\r\n  File \"/usr/local/lib/python3.6/site-packages/alembic/util/compat.py\", line 174, in load_module_py\r\n    spec.loader.exec_module(module)\r\n  File \"<frozen importlib._bootstrap_external>\", line 678, in exec_module\r\n  File \"<frozen importlib._bootstrap>\", line 219, in _call_with_frames_removed\r\n  File \"/usr/local/lib/python3.6/site-packages/mlflow/temporary_db_migrations_for_pre_1_users/env.py\", line 78, in <module>\r\n    run_migrations_online()\r\n  File \"/usr/local/lib/python3.6/site-packages/mlflow/temporary_db_migrations_for_pre_1_users/env.py\", line 72, in run_migrations_online\r\n    context.run_migrations()\r\n  File \"<string>\", line 8, in run_migrations\r\n  File \"/usr/local/lib/python3.6/site-packages/alembic/runtime/environment.py\", line 846, in run_migrations\r\n    self.get_context().run_migrations(**kw)\r\n  File \"/usr/local/lib/python3.6/site-packages/alembic/runtime/migration.py\", line 365, in run_migrations\r\n    step.migration_fn(**kw)\r\n  File \"/usr/local/lib/python3.6/site-packages/mlflow/temporary_db_migrations_for_pre_1_users/versions/ff01da956556_ensure_unique_constraint_names.py\", line 174, in upgrade\r\n    condition=column('lifecycle_stage').in_([\"active\", \"deleted\"])\r\n  File \"/usr/local/lib/python3.6/contextlib.py\", line 88, in __exit__\r\n    next(self.gen)\r\n  File \"/usr/local/lib/python3.6/site-packages/alembic/operations/base.py\", line 325, in batch_alter_table\r\n    impl.flush()\r\n  File \"/usr/local/lib/python3.6/site-packages/alembic/operations/batch.py\", line 79, in flush\r\n    fn(*arg, **kw)\r\n  File \"/usr/local/lib/python3.6/site-packages/alembic/ddl/impl.py\", line 241, in drop_constraint\r\n    self._exec(schema.DropConstraint(const))\r\n  File \"/usr/local/lib/python3.6/site-packages/alembic/ddl/impl.py\", line 134, in _exec\r\n    return conn.execute(construct, *multiparams, **params)\r\n  File \"/usr/local/lib/python3.6/site-packages/sqlalchemy/engine/base.py\", line 988, in execute\r\n    return meth(self, multiparams, params)\r\n  File \"/usr/local/lib/python3.6/site-packages/sqlalchemy/sql/ddl.py\", line 72, in _execute_on_connection\r\n    return connection._execute_ddl(self, multiparams, params)\r\n  File \"/usr/local/lib/python3.6/site-packages/sqlalchemy/engine/base.py\", line 1050, in _execute_ddl\r\n    compiled,\r\n  File \"/usr/local/lib/python3.6/site-packages/sqlalchemy/engine/base.py\", line 1253, in _execute_context\r\n    e, statement, parameters, cursor, context\r\n  File \"/usr/local/lib/python3.6/site-packages/sqlalchemy/engine/base.py\", line 1473, in _handle_dbapi_exception\r\n    util.raise_from_cause(sqlalchemy_exception, exc_info)\r\n  File \"/usr/local/lib/python3.6/site-packages/sqlalchemy/util/compat.py\", line 398, in raise_from_cause\r\n    reraise(type(exception), exception, tb=exc_tb, cause=cause)\r\n  File \"/usr/local/lib/python3.6/site-packages/sqlalchemy/util/compat.py\", line 152, in reraise\r\n    raise value.with_traceback(tb)\r\n  File \"/usr/local/lib/python3.6/site-packages/sqlalchemy/engine/base.py\", line 1249, in _execute_context\r\n    cursor, statement, parameters, context\r\n  File \"/usr/local/lib/python3.6/site-packages/sqlalchemy/engine/default.py\", line 552, in do_execute\r\n    cursor.execute(statement, parameters)\r\nsqlalchemy.exc.ProgrammingError: (psycopg2.errors.UndefinedTable) relation \"experiments\" does not exist\r\n\r\n[SQL: ALTER TABLE experiments DROP CONSTRAINT lifecycle_stage]\r\n(Background on this error at: http://sqlalche.me/e/f405)\r\n```\r\n","closed_by":null,"reactions":{"url":"https://api.github.com/repos/mlflow/mlflow/issues/2113/reactions","total_count":10,"+1":10,"-1":0,"laugh":0,"hooray":0,"confused":0,"heart":0,"rocket":0,"eyes":0},"timeline_url":"https://api.github.com/repos/mlflow/mlflow/issues/2113/timeline","performed_via_github_app":null,"state_reason":null}