{"url":"https://api.github.com/repos/labmlai/labml/issues/79","repository_url":"https://api.github.com/repos/labmlai/labml","labels_url":"https://api.github.com/repos/labmlai/labml/issues/79/labels{/name}","comments_url":"https://api.github.com/repos/labmlai/labml/issues/79/comments","events_url":"https://api.github.com/repos/labmlai/labml/issues/79/events","html_url":"https://github.com/labmlai/labml/issues/79","id":1023033661,"node_id":"I_kwDOCWiGGM48-kE9","number":79,"title":"502 - Bad Gateway","user":{"login":"EMalagoli92","id":92330921,"node_id":"U_kgDOBYDbqQ","avatar_url":"https://avatars.githubusercontent.com/u/92330921?v=4","gravatar_id":"","url":"https://api.github.com/users/EMalagoli92","html_url":"https://github.com/EMalagoli92","followers_url":"https://api.github.com/users/EMalagoli92/followers","following_url":"https://api.github.com/users/EMalagoli92/following{/other_user}","gists_url":"https://api.github.com/users/EMalagoli92/gists{/gist_id}","starred_url":"https://api.github.com/users/EMalagoli92/starred{/owner}{/repo}","subscriptions_url":"https://api.github.com/users/EMalagoli92/subscriptions","organizations_url":"https://api.github.com/users/EMalagoli92/orgs","repos_url":"https://api.github.com/users/EMalagoli92/repos","events_url":"https://api.github.com/users/EMalagoli92/events{/privacy}","received_events_url":"https://api.github.com/users/EMalagoli92/received_events","type":"User","site_admin":false},"labels":[],"state":"closed","locked":false,"assignee":null,"assignees":[],"milestone":null,"comments":2,"created_at":"2021-10-11T19:13:11Z","updated_at":"2021-11-02T20:45:14Z","closed_at":"2021-11-02T20:45:13Z","author_association":"NONE","active_lock_reason":null,"body":"Hi,\r\nsince yesterday, I constantly receive the message '502 Bad Gateway' every time I launch an labml experiment, both from jupyter notebook and from Colab. Here an example:\r\n\r\n![Schermata da 2021-10-11 21-10-26](https://user-images.githubusercontent.com/92330921/136844012-f87e7cb5-50e1-4d88-b40d-c4d692df222f.png)\r\n\r\n\r\nMoreover, I get this error from https://app.labml.ai/runs : \r\n![Schermata da 2021-10-11 21-04-28](https://user-images.githubusercontent.com/92330921/136843980-74dc2f04-ffcc-4872-b8b9-a1713ad70c4d.png)\r\n\r\nIs there a problem with your app?\r\n\r\n\r\nThanks in advantage.\r\n\r\n","closed_by":{"login":"EMalagoli92","id":92330921,"node_id":"U_kgDOBYDbqQ","avatar_url":"https://avatars.githubusercontent.com/u/92330921?v=4","gravatar_id":"","url":"https://api.github.com/users/EMalagoli92","html_url":"https://github.com/EMalagoli92","followers_url":"https://api.github.com/users/EMalagoli92/followers","following_url":"https://api.github.com/users/EMalagoli92/following{/other_user}","gists_url":"https://api.github.com/users/EMalagoli92/gists{/gist_id}","starred_url":"https://api.github.com/users/EMalagoli92/starred{/owner}{/repo}","subscriptions_url":"https://api.github.com/users/EMalagoli92/subscriptions","organizations_url":"https://api.github.com/users/EMalagoli92/orgs","repos_url":"https://api.github.com/users/EMalagoli92/repos","events_url":"https://api.github.com/users/EMalagoli92/events{/privacy}","received_events_url":"https://api.github.com/users/EMalagoli92/received_events","type":"User","site_admin":false},"reactions":{"url":"https://api.github.com/repos/labmlai/labml/issues/79/reactions","total_count":0,"+1":0,"-1":0,"laugh":0,"hooray":0,"confused":0,"heart":0,"rocket":0,"eyes":0},"timeline_url":"https://api.github.com/repos/labmlai/labml/issues/79/timeline","performed_via_github_app":null,"state_reason":"completed"}